<!-- The mjcf model for AMP -->
<!-- Contact us : motor_moon94@korea.ac.kr -->
<!-- degree information : radian to angle -->
<mujoco model="Atlas RILAB for AMP">
	<compiler angle="radian" meshdir="Meshes/"/>
	<statistic extent="2" center="0 0 1"/>
	<option timestep="0.001"/>
	<default>
		<motor ctrlrange="-.95 .95"/>
		<site type="sphere" size="0.005"/>
		<joint limited="true" damping="20"/>
		<geom contype="0" conaffinity="1" friction="0.7 0.1 0.1" margin="0.001" type="mesh" />
		<default class="body">
			<geom type="capsule" condim="1" friction="1.0 0.05 0.05" solimp=".9 .99 .003" solref=".015 1"/>
			<joint type="hinge" damping="0.1" stiffness="5" armature=".007" limited="true" solimplimit="0 .99 .01"/>
			<site size=".04" group="3"/>
			<default class="force-torque">
				<site type="box" size=".01 .01 .02" rgba="1 0 0 1" />
			</default>
			<default class="touch">
				<site type="capsule" rgba="0 0 1 .3"/>
			</default>
    	</default>
	</default>
	<asset>
		<mesh name="pelvis"         file="pelvis.stl"/>
		<mesh name="ltorso"         file="ltorso.stl"/>
		<mesh name="mtorso"         file="mtorso.stl"/>
		<mesh name="utorso"         file="utorso.stl"/>
		<mesh name="l_clav"         file="l_clav.stl"/>
		<mesh name="l_scap"         file="l_scap.stl"/>
		<mesh name="l_uarm"         file="l_uarm.stl"/>
		<mesh name="l_larm"         file="l_larm.stl"/>
		<mesh name="l_farm"         file="l_farm.stl"/>
		<mesh name="l_hand"			file="l_hand.stl"/>
		<mesh name="head"           file="head.stl"/>
		<mesh name="head_camera"    file="head_camera.stl"/>
		<mesh name="r_clav"         file="r_clav.stl"/>
		<mesh name="r_scap"         file="r_scap.stl"/>
		<mesh name="r_uarm"         file="r_uarm.stl"/>
		<mesh name="r_larm"         file="r_larm.stl"/>
		<mesh name="r_farm"         file="r_farm.stl"/>
		<mesh name="r_hand"         file="r_hand.stl"/>
		<mesh name="l_uglut"        file="l_uglut.stl"/>
		<mesh name="l_lglut"        file="l_lglut.stl"/>
		<mesh name="l_uleg"         file="l_uleg.stl"/>
		<mesh name="l_lleg"         file="l_lleg.stl"/>
		<mesh name="l_talus"        file="l_talus.stl"/>
		<mesh name="l_foot"         file="l_foot.stl"/>
		<mesh name="r_uglut"        file="r_uglut.stl"/>
		<mesh name="r_lglut"        file="r_lglut.stl"/>
		<mesh name="r_uleg"         file="r_uleg.stl"/>
		<mesh name="r_lleg"         file="r_lleg.stl"/>
		<mesh name="r_talus"        file="r_talus.stl"/>
		<mesh name="r_foot"         file="r_foot.stl"/>
		
		<texture name="groundplane" type="2d" builtin="checker" rgb1=".25 .26 .25" 
			rgb2=".22 .22 .22" width="100" height="100" mark="none" markrgb=".8 .8 .8"/>
		<material name="MatGnd" texture="groundplane"  texrepeat="20 20" specular="1" shininess=".3" reflectance="0.00001" rgba="1 1 1 1"/>
	</asset>
	<worldbody>
		<!-- GROUND -->
		<geom name="floor" type="plane" pos="0 0 0" size="10 10 1" conaffinity="1" contype="1" material="MatGnd"/>
		<light directional="true" cutoff="60" exponent="1" diffuse="1 1 1" specular=".1 .1 .1" pos="1 1 1.5" dir="-1 -1 -1.3"/>
		<body name="pelvis" pos="0 0 1" childclass="body">
			<freejoint name="root"/>
			<site name="root" class="force-torque"/>
			<!-- <geom group="1" rgba = "0.1 0.1 0.1 1" contype="0" mesh="pelvis" /> -->
			<geom type="capsule" pos="0.01 0 0.09" size="0.2 0.01" />
			<site name="pelvis" class="touch" type="capsule" pos="0.01 0 0.09" size="0.2 0.01" />
			<geom type="box" pos="-0.1 0 -0.05" size="0.05 0.075 0.1" />
			<site name="upper_waist" class="touch" type="box" pos="-0.1 0 -0.05" size="0.05 0.075 0.1" />
			<body name="ltorso" pos="-0.0125 0 0" >
				<inertial pos="-0.011298 -0.000003 0.074684" quat="0.498101 0.498096 -0.501893 0.501896" mass="1.62729" diaginertia="0.109733 0.064662 0.050298" />
				<joint name="back_lbz" type="hinge" pos="0 0 0" axis="0 0 1" range="-0.610865 0.610865" damping="35" stiffness="0"/>
				<!-- <geom group="1" rgba = "0.1 0.1 0.1 1" contype="0" mesh="ltorso" /> -->
				<geom name="ltorso" type="sphere" pos="0 0 0" size="0.01"/>
				<body name="mtorso" pos="0 0 0.09" >
					<joint name="back_mby" type="hinge" pos="0 0 0" axis="0 1 0" range="-1.2 1.28" damping="35" stiffness="0"/>
					<!-- <geom group="1" rgba = "0.1 0.1 0.1 1" contype="0" mesh="mtorso" /> -->
					<geom name="mtorso" type="sphere" pos="0 0 0" size="0.01"/>
					<body name="utorso" pos="0 0 0.05"   user="-6006">
						<joint name="back_ubx" type="hinge" pos="0 0 0" axis="1 0 0" range="-0.790809 0.790809" damping="35" stiffness="0"/>
						<!-- <geom group="1" rgba = "0.1 0.1 0.1 1" contype="0" mesh="utorso" /> -->
						<geom type="box" pos="0.0446 0 0.1869" size="0.1594 0.12 0.1581" />
						<site name="torso" class="touch" type="box" pos="0.0446 0 0.1869" size="0.1594 0.12 0.1581" />
						<geom type="capsule" pos="0.024 0.16 0.18" quat="0.965926 -0.258820 0 0" size="0.0363 0.111875"/>
						<geom type="capsule" pos="0.024 -0.16 0.18" quat="0.965926 0.258820 0 0" size="0.0363 0.111875"/>
						
						<body name="head" pos="0.21672 0 0.53796"  user="-6001">
							<!-- <inertial pos="-0.075493 0.000033 0.02774" quat="0.981276 -0.000974 0.192607 -0.000133" mass="1.41984" diaginertia="0.002489 0.002489 0.002489" /> -->
							<joint name="neck_ay" type="hinge" pos="0 0 0" axis="0 1 0" range="-0.610865 1.134464" damping="2" stiffness="0"/>
							<!-- <geom group="1" contype="0" rgba="0.9098 0.44314 0.031373 1" mesh="head" /> -->
							<geom type="box" pos="-0.0503 0 -0.00195" size="0.06555 0.06 0.02955" rgba="0.9098 0.44314 0.031373 1" />
							<geom type="box" pos="-0.093 0 0.0868" size="0.0234 0.06 0.0592" rgba="0.9098 0.44314 0.031373 1" />
							<site name="head" class="touch" type="box" pos="-0.093 0 0.0868" size="0.0234 0.06 0.0592" rgba="0.9098 0.44314 0.031373 1" />
						</body>
						<body name="r_clav" pos="0.024 -0.221 0.289">
							<!-- <inertial pos="0.014 -0.058 0.029" quat="-0.137950 0.693520 0.137950 0.693520" mass="2.369" diaginertia="0.007 0.006414 0.003586" /> -->
							<joint name="r_arm_usy" type="hinge" pos="0 0 0" axis="0 0.500000 -0.866025" range="-1.9635 1.9635" user="0 0.5" stiffness="0"/>
							<!-- <geom group="1" rgba = "0.1 0.1 0.1 1" contype="0" pos="-0.000934 -0.001693 0.069243" quat="0.414472 0.573149 0.415305 0.572044" mesh="r_clav" /> -->
							<geom type="capsule" pos="0 -0.0697 0.0261" quat="0.707107 0 0.707107 0" size="0.045 0.07625" />
							<geom type="box" pos="-0.005 0.0074 -0.0538" quat="0.866025 -0.500001 0 0" size="0.065 0.075 0.025" />
							<body name="r_scap" pos="0 -0.075 0.036" >
								<!-- <inertial pos="-0.002 -0.108 0" quat="0.5 0.5 -0.5 0.5" mass="2.707" diaginertia="0.013 0.01 0.005" /> -->
								<joint name="r_arm_shx" type="hinge" pos="0 0 0" axis="1 0 0" range="-1.74533 1.39626" user="0 1" stiffness="0"/>
								<!-- <geom group="1" rgba = "0.1 0.1 0.1 1" contype="0" mesh="r_scap" /> -->
								<geom type="capsule" pos="0.001 -0.12651 0.01521" quat="0.707107 0.707107 0 0" size="0.045 0.0625" />
								<geom type="box" pos="0.001 -0.05 0.016" size="0.075 0.075 0.03" />
								<site name="right_upper_arm" class="touch" type="box" pos="0.001 -0.05 0.016" size="0.075 0.075 0.03" />
								<body name="r_uarm" pos="0 -0.185 0" >
									<!-- <inertial pos="0.007 -0.114 0.008" quat="0.5 0.5 0.5 0.5" mass="1.881" diaginertia="0.003 0.003 0.002" /> -->
									<joint name="r_arm_ely" type="hinge" pos="0 0 0" axis="0 1 0" range="0 3.14159" user="0 1.5" stiffness="0"/>
									<!-- <geom group="1" rgba = "0.1 0.1 0.1 1" contype="0" mesh="r_uarm" /> -->
									<geom type="capsule" pos="0.001 -0.111 0" quat="0.707105 0 0.707108 0" size="0.045 0.0625" />
									<geom type="box" pos="0.001 -0.043 0.01" quat="0.707107 0 0.707107 0" size="0.02 0.035 0.065" />
									<site name="right_lower_arm" class="touch" type="box" pos="0.001 -0.043 0.01" quat="0.707107 0 0.707107 0" size="0.02 0.035 0.065" />
									<body name="r_larm" pos="0 -0.121 0.013" >
										<!-- <inertial pos="-0.003 -0.099 -0.014" quat="0.5 0.5 -0.5 0.5" mass="2.148" diaginertia="0.006 0.005 0.003" /> -->
										<joint name="r_arm_elx" type="hinge" pos="0 0 0" axis="1 0 0" range="-2.35619 0" user="0 -1" stiffness="0"/>
										<!-- <geom group="1" rgba = "0.1 0.1 0.1 1" contype="0" mesh="r_larm" /> -->
										<geom type="capsule" pos="0.001 -0.127 0" quat="0.707107 0.707107 0 0" size="0.045 0.0625" />
										<geom type="box" pos="0.001 -0.051 0" size="0.0675 0.075 0.03" />
										<body name="r_farm" pos="0 -0.188 -0.013" >
											<!-- <inertial pos="0 -0.041 0" quat="0.707107 0.707107 0 0" mass="0.981" diaginertia="0.003 0.003 0.001" /> -->
											<joint name="r_arm_uwy" type="hinge" pos="0 0 0" axis="0 1 0" range="-1.571 1.571" stiffness="0" />
											<!-- <geom group="1" rgba = "0.1 0.1 0.1 1" contype="0" pos="0.000654 0.018685 -0.001301" quat="0.707067 0.707069 -0.007393 -0.007393" mesh="r_farm" /> -->
											<geom type="capsule" pos="0 -0.065 0.004" quat="0.707105 0 0.707108 0" size="0.045 0.0625" />
											<geom type="box" pos="0.001 -0.015 -0.002" size="0.0675 0.05 0.0225" />
											<body name="r_hand" pos="0 -0.058 0" >
												<!-- <inertial pos="0 -0.093 0" quat="0.707107 0.707107 0 0" mass="2.263" diaginertia="0.01 0.01 0.002" /> -->
												<joint name="r_arm_mwx" type="hinge" pos="0 0 0" axis="1 0 0" range="-1.571 0.436" user="9001" stiffness="0"/>
												<!-- <geom group="1" rgba = "0.1 0.1 0.1 1" contype="0" mesh="r_hand" /> -->
												<geom type="capsule" pos="0.001 -0.1 0.01" quat="0.707107 0.707107 0 0" size="0.03 0.025" />
												<geom type="box" pos="0.001 -0.05 0.01" size="0.065 0.045 0.035" />
												<site name="right_hand" class="touch" type="box" pos="0.001 -0.05 0.01" size="0.065 0.045 0.035" />
											</body>
										</body>
									</body>
								</body>
							</body>
						</body>

						<body name="l_clav" pos="0.024 0.221 0.289">
							<joint name="l_arm_usy" type="hinge" pos="0 0 0" axis="0 0.500000 0.866025" range="-1.9635 1.9635" user="0 0.5" stiffness="0"/>
							<!-- <geom group="1" rgba = "0.1 0.1 0.1 1" contype="0" pos="-0.000934 0.001692 0.069242" quat="-0.414459 0.573156 -0.415293 0.572056" mesh="l_clav" /> -->
							<geom type="capsule" pos="0 0.0697 0.0261" quat="0.707107 0 0.707107 0" size="0.045 0.07625"/>
							<geom type="box" pos="-0.005 -0.0074 -0.0538" quat="0.866025 0.500001 0 0" size="0.065 0.075 0.025"/>
							<body name="l_scap" pos="0 0.075 0.036" >
								<joint name="l_arm_shx" type="hinge" pos="0 0 0" axis="1 0 0" range="-1.39626 1.74533" user="0 -1" stiffness="0"/>
								<!-- <geom group="1" rgba = "0.1 0.1 0.1 1" contype="0" mesh="l_scap" /> -->
								<geom type="capsule" pos="0.001 0.12651 0.01521" quat="0.707107 0.707107 0 0" size="0.045 0.0625" />
								<geom type="box" pos="0.001 0.05 0.016" size="0.075 0.075 0.03" />
								<site name="left_upper_arm" class="touch" type="box" pos="0.001 0.05 0.016" size="0.075 0.075 0.03" />
								<body name="l_uarm" pos="0 0.185 0" >
									<joint name="l_arm_ely" type="hinge" pos="0 0 0" axis="0 1 0" range="0 3.14159" user="0 1.5" stiffness="0"/>
									<!-- <geom group="1" rgba = "0.1 0.1 0.1 1" contype="0" mesh="l_uarm" /> -->
									<geom type="capsule" pos="0.001 0.111 0" quat="0.707105 0 0.707108 0" size="0.045 0.0625" />
									<geom type="box" pos="0.001 0.043 0.01" quat="0.707107 0 0.707107 0" size="0.02 0.035 0.065" />
									<site name="left_lower_arm" class="touch" type="box" pos="0.001 0.043 0.01" quat="0.707107 0 0.707107 0" size="0.02 0.035 0.065" />
									<body name="l_larm" pos="0 0.121 0.013" >
										<joint name="l_arm_elx" type="hinge" pos="0 0 0" axis="1 0 0" range="0 2.35619" user="0 1" stiffness="0"/>
										<!-- <geom group="1" rgba = "0.1 0.1 0.1 1" contype="0" mesh="l_larm" /> -->
										<geom type="capsule" pos="0.001 0.127 0" quat="0.707107 0.707107 0 0" size="0.045 0.0625" />
										<geom type="box" pos="0.001 0.051 0" size="0.0675 0.075 0.03" />
										<body name="l_farm" pos="0 0.188 -0.013" >
											<joint name="l_arm_uwy" type="hinge" pos="0 0 0" axis="0 1 0" range="-1.571 1.571" stiffness="0"/>
											<!-- <geom group="1" rgba = "0.1 0.1 0.1 1" contype="0" pos="0.000654 -0.018685 -0.001301" quat="0.707069 0.707067 0.007393 0.007393" mesh="l_farm" /> -->
											<geom type="capsule" pos="0 0.065 0.004" quat="0.707105 0 0.707108 0" size="0.045 0.0625" />
											<geom type="box" pos="0.001 0.015 -0.002" size="0.0675 0.05 0.0225" />
											<body name="l_hand" pos="0 0.058 0" >
												<joint name="l_arm_mwx" type="hinge" pos="0 0 0" axis="1 0 0" range="-0.436 1.571" user="9001" stiffness="0"/>
												<!-- <geom group="1" rgba = "0.1 0.1 0.1 1" contype="0" mesh="l_hand" /> -->
												<geom type="capsule" pos="0.001 0.1 0.01" quat="0.707107 0.707107 0 0" size="0.03 0.025" />
												<geom type="box" pos="0.001 0.05 0.01" size="0.065 0.045 0.035"/>
												<site name="left_hand" class="touch" type="box" pos="0.001 0.05 0.01" size="0.065 0.045 0.035"/>
											</body>
										</body>
									</body>
								</body>
							</body>
						</body>


					</body>
				</body>
			</body>
			<body name="r_uglut" pos="0 -0.089 0" >
				<!-- <inertial pos="0.005293 0.003447 0.003130" quat="1.000000 0.000002 0.000547 0.000001" mass="1.51622" diaginertia="0.019094 0.019094 0.019094" /> -->
				<joint name="r_leg_uhz" type="hinge" pos="0 0 0" axis="0 0 1" range="-1.14 0.32" />
				<!-- <geom group="1" rgba = "0.1 0.1 0.1 1" contype="0" mesh="r_uglut" /> -->
				<geom type="capsule" pos="0 0 0" quat="0.707107 0 0.707107 0" size="0.019096 0.039198" />
				<!-- <geom type="capsule" pos="0 0 0" size="0.019841 0.040421" /> -->
				<body name="r_lglut" pos="0 0 0" >
					<!-- <inertial pos="0.013334 -0.017048 -0.031205" quat="0.999977 -0.006717 -0.000034 0.000401" mass="0.803" diaginertia="0.023308 0.023308 0.023308" /> -->
					<joint name="r_leg_mhx" type="hinge" pos="0 0 0" axis="1 0 0" range="-0.495 0.47" />
					<!-- <geom group="1" rgba = "0.1 0.1 0.1 1" contype="0" mesh="r_lglut" /> -->
					<geom type="capsule" pos="0.049968 -0.022488 -0.050117" quat="0.707107 0.707107 0 0" size="0.020097 0.030153" />
					<geom type="capsule" pos="0 0 0" quat="0.707107 0 0.707107 0" size="0.02 0.06" />
					<body name="r_uleg" pos="0.05 0 -0.05" >
						<site name="right_hip" class="force-torque"/>
						<!-- <inertial pos="0 0 -0.21" quat="0.707107 0 0 0.707107" mass="7.227" diaginertia="0.047502 0.047502 0.047502" /> -->
						<joint name="r_leg_lhy" type="hinge" pos="0 0 0" axis="0 1 0" range="-1.745 0.524"/>
						<!-- <geom 	group="1" rgba = "0.1 0.1 0.1 1" contype="0" mesh="r_uleg" /> -->
						<geom type="capsule" pos="-0.0179 -0.02085 -0.13" size="0.1 0.08" />
						<site name="right_thigh" class="touch" type="capsule" pos="-0.0179 -0.02085 -0.13" size="0.1 0.08" />
						<!-- <geom type="capsule" pos="-0.03 -0.01 -0.23" quat="0.988771 0 -0.149438 0" size="0.07 0.075" /> -->
						<!-- <geom type="capsule" pos="-0.005 -0.01 -0.23" quat="0.988771 0 0.149438 0" size="0.07 0.075" /> -->
						<geom type="capsule" pos="-0.02 -0.03 -0.23" quat="0.992198 0.124675 0 0" size="0.07 0.075" />
						<body name="r_lleg" pos="-0.05 0 -0.374" >
							<site name="right_knee" class="force-torque"/>
							<!-- <inertial pos="0.001 0 -0.187" quat="0.999751 0 0.022327 0" mass="4.367" diaginertia="0.077134 0.076 0.009866" /> -->
							<joint name="r_leg_kny" type="hinge" pos="0 0 0" axis="0 1 0" range="0 2.45"/>
							<!-- <geom group="1" rgba = "0.1 0.1 0.1 1" contype="0" mesh="r_lleg" /> -->
							<geom type="capsule" pos="0.02 -0.00295 -0.18" quat="0.998750 0 0.049979 0" size="0.07 0.2" />
							<site name="right_shin" class="touch" type="capsule" pos="0.02 -0.00295 -0.18" quat="0.998750 0 0.049979 0" size="0.07 0.2" />
							<body name="r_talus" pos="0 0 -0.422" >
								<site name="right_ankle" class="force-torque"/>
								<inertial pos="0 0 0" quat="0 0.707107 0 0.707107" mass="0.867" diaginertia="0.004007 0.003504 0.001" />
								<joint name="r_leg_uay" type="hinge" pos="0 0 0" axis="0 1 0" range="-0.698 0.698" />
								<!-- <geom group="1" rgba = "0.1 0.1 0.1 1" contype="0" mesh="r_talus" /> -->
								<geom type="capsule" pos="0 0 0" quat="0.707107 0 0.707107 0" size="0.010181 0.014771" />
								<geom type="capsule" pos="0 0 0" quat="0.707107 0.707107 0 0" size="0.010348 0.005030" />
								<body name="r_foot" pos="0 0 0"  user ="-6008">
									<!-- <inertial pos="0.027 0 -0.067" quat="0 0.707107 0 0.707107" mass="0.867" diaginertia="0.004007 0.003504 0.002" /> -->
									<joint name="r_leg_lax" type="hinge" pos="0 0 0" axis="1 0 0" range="-0.436 0.436" />
									<!-- <geom group="1" rgba = "0.1 0.1 0.1 1" contype="0" mesh="r_foot" /> -->
									<geom type="box" pos="0.048 0 -0.056119" size="0.13 0.062443 0.025" />
									<site name="right_foot" class="touch" type="box" pos="0.048 0 -0.056119" size="0.13 0.062443 0.025" />
								</body>
							</body>
						</body>
					</body>
				</body>
			</body>
			<body name="l_uglut" pos="0 0.089 0" >
				<!-- <inertial pos="0.005293 -0.003447 0.003130" quat="1.000000 -0.000002 0.000547 -0.000001" mass="1.51622" diaginertia="0.019094 0.019094 0.019094" /> -->
				<joint name="l_leg_uhz" type="hinge" pos="0 0 0" axis="0 0 1" range="-0.32 1.14" />
				<!-- <geom group="1" rgba = "0.1 0.1 0.1 1" contype="0" mesh="l_uglut" /> -->
				<geom type="capsule" pos="0 0 0" quat="0.707107 0 0.707107 0" size="0.019096 0.039198" />
				<!-- <geom type="capsule" pos="0 0 0" size="0.019841 0.040421" /> -->
				<body name="l_lglut" pos="0 0 0" >
					<!-- <inertial pos="0.013334 0.017048 -0.031205" quat="0.999977 0.006717 -0.000034 -0.000401" mass="0.803" diaginertia="0.023308 0.023308 0.023308" /> -->
					<joint name="l_leg_mhx" type="hinge" pos="0 0 0" axis="1 0 0" range="-0.47 0.495" />
					<!-- <geom group="1" rgba = "0.1 0.1 0.1 1" contype="0" mesh="l_lglut" /> -->
					<geom type="capsule" pos="0.049968 0.022488 -0.050117" quat="0.707107 0.707107 0 0" size="0.020097 0.030153" />
					<geom type="capsule" pos="0 0 0" quat="0.707107 0 0.707107 0" size="0.02 0.06" />
					<body name="l_uleg" pos="0.05 0 -0.05" >
						<site name="left_hip" class="force-torque"/>
						<inertial pos="0 0 -0.21" quat="0.707107 0 0 0.707107" mass="7.227" diaginertia="0.047502 0.047502 0.047502" />
						<joint name="l_leg_lhy" type="hinge" pos="0 0 0" axis="0 1 0" range="-1.75 0.524"/>
						<!-- <geom group="1" rgba = "0.1 0.1 0.1 1" contype="0" mesh="l_uleg" /> -->
						<geom type="capsule" pos="-0.0179 0.02085 -0.13" size="0.1 0.08"/>
						<site name="left_thigh" class="touch" type="capsule" pos="-0.0179 0.02085 -0.13" size="0.1 0.08"/>
						<!-- <geom type="capsule" pos="-0.03 0.01 -0.23" quat="0.988771 0 -0.149438 0" size="0.07 0.075" /> -->
						<!-- <geom type="capsule" pos="-0.005 0.01 -0.23" quat="0.988771 0 0.149438 0" size="0.07 0.075" /> -->
						<geom type="capsule" pos="-0.02 0.03 -0.23" quat="0.992198 -0.124675 0 0" size="0.07 0.075" />
						<body name="l_lleg" pos="-0.05 0 -0.374" >
							<site name="left_knee" class="force-torque"/>
							<!-- <inertial pos="0.001 0 -0.187" quat="0.999751 0 0.022327 0" mass="4.367" diaginertia="0.077134 0.076 0.009866" /> -->
							<joint name="l_leg_kny" type="hinge" pos="0 0 0" axis="0 1 0" range="0 2.45"/>
							<!-- <geom group="1" rgba = "0.1 0.1 0.1 1" contype="0" mesh="l_lleg" /> -->
							<geom type="capsule" pos="0.02 0.00295 -0.18" quat="0.998750 0 0.049979 0" size="0.07 0.2" />
							<site name="left_shin" class="touch" type="capsule" pos="0.02 0.00295 -0.18" quat="0.998750 0 0.049979 0" size="0.07 0.2" />
							<body name="l_talus" pos="0 0 -0.422" >
								<site name="left_ankle" class="force-torque"/>
								<!-- <inertial pos="0 0 0" quat="0 0.707107 0 0.707107" mass="0.867" diaginertia="0.004007 0.003504 0.001" /> -->
								<joint name="l_leg_uay" type="hinge" pos="0 0 0" axis="0 1 0" range="-0.698 0.698" />
								<!-- <geom group="1" rgba = "0.1 0.1 0.1 1" contype="0" mesh="l_talus" /> -->
								<geom type="capsule" pos="0 0 0" quat="0.707107 0 0.707107 0" size="0.010181 0.014771" />
								<geom type="capsule" pos="0 0 0" quat="0.707107 0.707107 0 0" size="0.010348 0.005030" />
								<body name="l_foot" pos="0 0 0"  user ="-6007">
									<!-- <inertial pos="0.027 0 -0.067" quat="0 0.707107 0 0.707107" mass="0.867" diaginertia="0.004007 0.003504 0.002" /> -->
									<joint name="l_leg_lax" type="hinge" pos="0 0 0" axis="1 0 0" range="-0.436 0.436" />
									<!-- <geom group="1" rgba = "0.1 0.1 0.1 1" contype="0" mesh="l_foot" /> -->
									<geom type="box" pos="0.048 0 -0.056119" size="0.13 0.062443 0.025" />
									<site name="left_foot" class="touch" type="box" pos="0.048 0 -0.056119" size="0.13 0.062443 0.025" />
								</body>
							</body>
						</body>
					</body>
				</body>
			</body>
		</body>
	</worldbody>
	<actuator>
		<!-- torso -->
		<motor name="back_lbz_actuator" joint="back_lbz" gear="124"/>
		<motor name="back_mby_actuator" joint="back_mby" gear="206"/>
		<motor name="back_ubx_actuator" joint="back_ubx" gear="95"/>

		<!-- left arm -->
		<motor name="l_arm_usy_actuator" joint="l_arm_usy" gear="212"/>
		<motor name="l_arm_shx_actuator" joint="l_arm_shx" gear="170"/>
		<motor name="l_arm_ely_actuator" joint="l_arm_ely" gear="114"/>
		<motor name="l_arm_elx_actuator" joint="l_arm_elx" gear="114"/>
		<motor name="l_arm_uwy_actuator" joint="l_arm_uwy" gear="114"/>
		<motor name="l_arm_mwx_actuator" joint="l_arm_mwx" gear="60"/>

		<!-- head -->
		<motor name="neck_ay_actuator" 	 joint="neck_ay" 	gear="5"/>

		<!-- right arm -->
		<motor name="r_arm_usy_actuator" joint="r_arm_usy" gear="212"/>
		<motor name="r_arm_shx_actuator" joint="r_arm_shx" gear="170"/>
		<motor name="r_arm_ely_actuator" joint="r_arm_ely" gear="114"/>
		<motor name="r_arm_elx_actuator" joint="r_arm_elx" gear="114"/>
		<motor name="r_arm_uwy_actuator" joint="r_arm_uwy" gear="114"/>
		<motor name="r_arm_mwx_actuator" joint="r_arm_mwx" gear="60"/>

		<!-- left leg -->
		<motor name="l_leg_uhz_actuator" joint="l_leg_uhz" gear="110"/>
		<motor name="l_leg_mhx_actuator" joint="l_leg_mhx" gear="180"/>
		<motor name="l_leg_lhy_actuator" joint="l_leg_lhy" gear="260"/>
		<motor name="l_leg_kny_actuator" joint="l_leg_kny" gear="400"/>
		<motor name="l_leg_uay_actuator" joint="l_leg_uay" gear="220"/>
		<motor name="l_leg_lax_actuator" joint="l_leg_lax" gear="90"/>

		<!-- right leg -->
		<motor name="r_leg_uhz_actuator" joint="r_leg_uhz" gear="110"/>
		<motor name="r_leg_mhx_actuator" joint="r_leg_mhx" gear="180"/>
		<motor name="r_leg_lhy_actuator" joint="r_leg_lhy" gear="260"/>
		<motor name="r_leg_kny_actuator" joint="r_leg_kny" gear="400"/>
		<motor name="r_leg_uay_actuator" joint="r_leg_uay" gear="220"/>
		<motor name="r_leg_lax_actuator" joint="r_leg_lax" gear="90"/>
	</actuator>

	<sensor>
		<subtreelinvel name="pelvis_subtreelinvel" body="pelvis"/>
		<accelerometer name="root_accel"    site="root"/>
		<velocimeter name="root_vel"        site="root"/>
		<gyro name="root_gyro"              site="root"/>

		<force name="left_ankle_force"       site="left_ankle"/>
		<force name="right_ankle_force"      site="right_ankle"/>
		<force name="left_knee_force"        site="left_knee"/>
		<force name="right_knee_force"       site="right_knee"/>
		<force name="left_hip_force"         site="left_hip"/>
		<force name="right_hip_force"        site="right_hip"/>

		<torque name="left_ankle_torque"     site="left_ankle"/>
		<torque name="right_ankle_torque"    site="right_ankle"/>
		<torque name="left_knee_torque"      site="left_knee"/>
		<torque name="right_knee_torque"     site="right_knee"/>
		<torque name="left_hip_torque"       site="left_hip"/>
		<torque name="right_hip_torque"      site="right_hip"/>

		<touch name="pelvis_touch"           site="pelvis"/>
		<touch name="upper_waist_touch"      site="upper_waist"/>
		<touch name="torso_touch"            site="torso"/>
		<touch name="head_touch"             site="head"/>
		<touch name="right_upper_arm_touch"  site="right_upper_arm"/>
		<touch name="right_lower_arm_touch"  site="right_lower_arm"/>
		<touch name="right_hand_touch"       site="right_hand"/>
		<touch name="left_upper_arm_touch"   site="left_upper_arm"/>
		<touch name="left_lower_arm_touch"   site="left_lower_arm"/>
		<touch name="left_hand_touch"        site="left_hand"/>
		<touch name="right_thigh_touch"      site="right_thigh"/>
		<touch name="right_shin_touch"       site="right_shin"/>
		<touch name="right_foot_touch"       site="right_foot"/>
		<touch name="left_thigh_touch"       site="left_thigh"/>
		<touch name="left_shin_touch"        site="left_shin"/>
		<touch name="left_foot_touch"        site="left_foot"/>
	</sensor>

</mujoco>
